// asynchronus , synchronous error ko handle kare automatically 

export const catchAsyncErrors = (theFunction) => {
    return (req, res, next) => {
      Promise.resolve(theFunction(req, res, next)).catch(next);
    };
  };